Workbook

Sheet 逐题回测·归位矩阵
A1: 序号 | B1: 年份 | C1: 区 | D1: 场次 | E1: 题号 | F1: 题型 | G1: 主导环节 | H1: 核心考点（复合） | I1: 外溢 | J1: 设问摘要
A2: 1 | B2: 2024 | C2: 东城 | D2: 一模 | E2: 第19题 | F2: T1判责/理由 | G2: ③定责 | H2: 诉讼时效，婚姻家庭继承，民法原则 | J2: 针对上述案件，运用《法律与生活》知识，谈谈法律规定诉讼时效并对其不适用的情形加以规定的原因。
A3: 2 | B3: 2025 | C3: 东城 | D3: 二模 | E3: 第19题 | F3: T2补表/补链 | G3: ①②权利与关系 | H3: 行为能力·效力，名誉权，生命身体健康权，合同，侵权·归责，消费者，民法原则 | J3: 阅读材料，完成下表。案件；体现的民法原则；以案说法；典型意义 案件一 ；守法和公序良俗原则；
A4: 3 | B4: 2025 | C4: 西城 | D4: 二模 | E4: 第18题 | F4: T1判责/理由 | G4: ③定责 | H4: 行为能力·效力，侵权·归责，婚姻家庭继承，民法原则 | J4: 结合材料，运用《法律与生活》的知识，分析人民法院的判决结果。
A5: 4 | B5: 2026 | C5: 房山 | D5: 一模 | E5: 第17题第1问 | F5: T3辨析/评析 | G5: ①主体与权利 | H5: 主体资格，合同，侵权·归责 | J5: （1）结合材料，运用“民事法律关系”知识，辨析“AI 幻觉造成损失谁买单”。（3分）
A6: 5 | B6: 2026 | C6: 西城 | D6: 二模 | E6: 第18题第1问 | F6: T1判责/理由 | G6: ③定责 | H6: 主体资格，行为能力·效力，合同，侵权·归责，纠纷解决·程序 | J6: （1）结合材料，阐明本案判决的法律依据（4分）
A7: 6 | B7: 2026 | C7: 延庆 | D7: 一模 | E7: 第18题第1问 | F7: T1判责/理由 | G7: ③定责 | H7: 肖像权，名誉权，侵权·归责，知产·竞争，消费者，民法原则 | J7: （1）结合 材料一 ，运用《法律与生活》知识，分析 M 公司涉嫌哪些违法行为，若主持人李某诉
A8: 7 | B8: 2026 | C8: 石景山 | D8: 二模 | E8: 第19题 | F8: T4意义/价值 | G8: ⑤升价值 | H8: 生命身体健康权 | J8: 结合材料，运用《法律与生活》知识，谈谈对未成年人校园欺凌违法行为“惩”“教”并行的认识。
A9: 8 | B9: 2026 | C9: 顺义 | D9: 二模 | E9: 第18题第2问 | F9: T4意义/价值 | G9: ⑤升价值 | H9: 隐私·个人信息，纠纷解决·程序 | I9: 必修三 | J9: 结合材料，运用法治知识，谈谈该开源智能体可能会侵犯用户的哪些民事权利，并分析如何规避该开源智
A10: 9 | B10: 2024 | C10: 顺义思政 | D10: 二模 | E10: 第17题 | F10: T4意义/价值 | G10: ⑤升价值 | H10: 主体资格，物权·相邻，知产·竞争，民法原则 | J10: 结合材料，运用所学知识，说明我国财产制度改革如何助力经济社会发展。
A11: 10 | B11: 2025 | C11: 东城 | D11: 期末 | E11: 第19题第1问 | F11: T2补表/补链 | G11: ①②权利与关系 | H11: 物权·相邻 | J11: （1）遇到的法律问题：________、________。（2分）
A12: 11 | B12: 2025 | C12: 朝阳 | D12: 二模 | E12: 第20题第1问 | F12: T1判责/理由 | G12: ③定责 | H12: 隐私·个人信息，物权·相邻，侵权·归责 | J12: (1)结合材料,运用《法律与生活》知识,分析上述案例。(8分)
A13: 12 | B13: 2025 | C13: 朝阳 | D13: 二模 | E13: 第20题第2问 | F13: T5对策/维权 | G13: ④解纷·对策 | H13: 物权·相邻，侵权·归责，纠纷解决·程序 | J13: (2)假如你是人民调解员,提出解决上述纠纷的建议。(2分)
A14: 13 | B14: 2025 | C14: 顺义 | D14: 一模 | E14: 第19题第1问 | F14: T1判责/理由 | G14: ④解纷·程序 | H14: 物权·相邻，侵权·归责，知产·竞争，消费者，民法原则，纠纷解决·程序 | J14: (1)运用《法律与生活》知识，分析上述案例是如何解决纠纷的。 案例1 : 案例2 :
A15: 14 | B15: 2025 | C15: 顺义 | D15: 一模 | E15: 第19题第2问 | F15: T4意义/价值 | G15: ⑤升价值 | H15: 主体资格，侵权·归责，纠纷解决·程序 | J15: (2)结合 材料一 与 材料二 ，运用法治知识，阐释定分止争的价值。
A16: 15 | B16: 2026 | C16: 西城 | D16: 一模 | E16: 第17题 | F16: T4意义/价值 | G16: ⑤升价值 | H16: 物权·相邻，侵权·归责，民法原则 | J16: 结合材料，运用法律相关知识，说明民法典物权编的上述规定如何推动国家绿色发展。
A17: 16 | B17: 2026 | C17: 通州 | D17: 期末 | E17: 第19题第1问 | F17: T1判责/理由 | G17: ③定责 | H17: 物权·相邻，合同 | J17: （1）结合材料，运用《法律与生活》知识，分析判决结果并说明理由。
A18: 17 | B18: 2024 | C18: 东城 | D18: 二模 | E18: 第19题第1问 | F18: T1判责/理由 | G18: ③定责 | H18: 合同，民法原则 | J18: （1）请你选择其中一方进行代理，并撰写起诉状。（7分）民事起诉状原告：被告：诉讼请求：事实与
A19: 18 | B19: 2024 | C19: 东城 | D19: 二模 | E19: 第19题第2问 | F19: T5对策/维权 | G19: ④解纷·对策 | H19: 行为能力·效力，民法原则 | J19: （2）为避免类似问题产生，我们应该________。（2分）
A20: 19 | B20: 2024 | C20: 朝阳 | D20: 一模 | E20: 第19题 | F20: T4意义/价值 | G20: ⑤升价值 | H20: 主体资格，合同，消费者，民法原则 | J20: 结合材料，运用《法律与生活》知识，分析诚信原则对促进社会主义市场经济健康发展的积极作用。
A21: 20 | B21: 2024 | C21: 石景山 | D21: 一模 | E21: 第17题 | F21: T1判责/理由 | G21: ③定责 | H21: 主体资格，行为能力·效力，合同，民法原则，纠纷解决·程序 | J21: 运用法律知识，结合案情，说明甲乙两公司合同成立的理由，并从民法基本原则角 度阐述该司法判决的
... A28: 27 | B28: 2026 | C28: 海淀 | D28: 期末 | E28: 第18题第1问 | F28: T1判责/理由 | G28: ③定责 | H28: 合同，民法原则 | J28: 运用《法律与生活》知识，判断这一条款是否有效，并说明理由。（6分）
A29: 28 | B29: 2026 | C29: 海淀 | D29: 期末 | E29: 第18题第2问 | F29: T4意义/价值 | G29: ⑤升价值 | H29: 合同 | I29: 必修三 | J29: 运用法治知识，分析《住房租赁条例》上述规定的现实意义。（6分）
A30: 29 | B30: 2024 | C30: 海淀 | D30: 一模 | E30: 第19题 | F30: T1判责/理由 | G30: ③定责 | H30: 主体资格，侵权·归责，知产·竞争，民法原则 | I30: 必修三 | J30: 运用《法律与生活》知识，谈谈对本案判决的认识。
A31: 30 | B31: 2025 | C31: 丰台 | D31: 一模 | E31: 第19题 | F31: T1判责/理由 | G31: ③定责 | H31: 侵权·归责，知产·竞争 | I31: 必修四经济 | J31: 结合材料，运用法治相关知识，分析本案作为人民法院保护科技创新典型案例的意义。
A32: 31 | B32: 2025 | C32: 丰台 | D32: 二模 | E32: 第19题第2问 | F32: T4意义/价值 | G32: ⑤升价值 | H32: 侵权·归责，民法原则 | J32: (2)一纸司法建议，既为当下划定了红线，防止技术滥用，又为未来创新发展预留了空间。 运用《法
A33: 32 | B33: 2025 | C33: 房山 | D33: 一模 | E33: 第19题 | F33: T4意义/价值 | G33: ⑤升价值 | H33: 侵权·归责，知产·竞争，劳动 | I33: 必修三，必修四经济 | J33: 结合材料，谈谈“真创新”受到“真保护”的法治价值。
A34: 33 | B34: 2025 | C34: 昌平 | D34: 二模 | E34: 第20题第1问 | F34: T1判责/理由 | G34: ③定责 | H34: 侵权·归责，知产·竞争 | J34: （1）阅读材料，运用《法律与生活》知识，完成 案件一 的 裁判理由 。（本空3分，本题共6分
A35: 34 | B35: 2025 | C35: 朝阳 | D35: 期末 | E35: 第20题 | F35: T2补表/补链 | G35: ①②权利与关系 | H35: 生命身体健康权，合同，侵权·归责，知产·竞争，消费者，民法原则 | I35: 必修三 | J35: 参考示例，完成下表。
A36: 35 | B36: 2025 | C36: 海淀 | D36: 二模 | E36: 第18题 | F36: T2补表/补链 | G36: ①②权利与关系 | H36: 侵权·归责，知产·竞争，民法原则，纠纷解决·程序 | I36: 必修三 | J36: 运用法治知识，将笔记中划线处补充完整。
A37: 36 | B37: 2025 | C37: 西城 | D37: 期末 | E37: 第19题 | F37: T1判责/理由 | G37: ③定责 | H37: 侵权·归责，知产·竞争，民法原则 | J37: “唤醒词”亦受法律保护，请运用法律知识分析法院的判决。
A38: 37 | B38: 2026 | C38: 东城 | D38: 一模 | E38: 第18题 | F38: T4意义/价值 | G38: ⑤升价值 | H38: 侵权·归责，知产·竞争，民法原则，纠纷解决·程序 | I38: 必修三 | J38: 结合材料，运用《法律与生活》知识，谈谈法院是如何以司法之力守护“向新力”的。
A39: 38 | B39: 2026 | C39: 东城 | D39: 二模 | E39: 第19题 | F39: T3辨析/评析 | G39: ③定责 | H39: 合同，知产·竞争，劳动，民法原则 | J39: 结合材料，运用《法律与生活》知识，评析乙公司和张某的行为。
A40: 39 | B40: 2026 | C40: 房山 | D40: 二模 | E40: 第18题第1问 | F40: T5对策/维权 | G40: ④解纷·对策 | H40: 名誉权，知产·竞争 | J40: 结合 材料一 ，运用《法律与生活》知识，分析上述场景可能涉及的法律边界，并提出应对措施。（7
A41: 40 | B41: 2026 | C41: 朝阳 | D41: 一模 | E41: 第18题 | F41: T5对策/维权 | G41: ④解纷·对策 | H41: 侵权·归责，知产·竞争，民法原则，纠纷解决·程序 | J41: 结合材料，运用《法律与生活》知识，谈谈人民法院是如何依法保护知识产权以护航新质生产力发展的。
A42: 41 | B42: 2026 | C42: 海淀 | D42: 二模 | E42: 第18题第2问 | F42: T4意义/价值 | G42: ⑤升价值 | H42: 知产·竞争 | J42: （2）结合 材料二 ，运用《法律与生活》知识，分析上述关于知识产权的法律规定是如何助力企业创
A43: 42 | B43: 2026 | C43: 海淀 | D43: 期末 | E43: 第19题 | F43: T1判责/理由 | G43: ③定责 | H43: 侵权·归责，知产·竞争，消费者 | J43: 运用《法律与生活》知识，谈谈对本案判决的认识。
A44: 43 | B44: 2026 | C44: 西城 | D44: 期末 | E44: 第17题 | F44: T1判责/理由 | G44: ③定责 | H44: 主体资格，知产·竞争，消费者，民法原则 | J44: 运用法律知识，分析法院的上述判决。
A45: 44 | B45: 2024 | C45: 丰台 | D45: 一模 | E45: 第17题 | F45: T1判责/理由 | G45: ③定责 | H45: 生命身体健康权，侵权·归责，民法原则 | I45: 必修三 | J45: 结合材料，运用《法律与生活》知识，谈谈法院酌情减轻被告赔偿责任的法理依据和现实意义。
A46: 45 | B46: 2024 | C46: 丰台 | D46: 二模 | E46: 第17题 | F46: T4意义/价值 | G46: ⑤升价值 | H46: 主体资格，侵权·归责，知产·竞争，民法原则 | J46: 运用《法律与生活》知识，结合上述案例分析民法典的相关规定对保护生态环境的作用。
...

Sheet 题型频次
A1: 题型 | B1: 题量 | C1: 占比 | D1: 说明
A2: T1判责/理由 | B2: =COUNTIF(逐题回测·归位矩阵!F:F,A2) -> 33 | C2: =B2/$B$8 -> 0.44594595 | D2: 分析判决/谁担责/法理依据——主力题
A3: T4意义/价值 | B3: =COUNTIF(逐题回测·归位矩阵!F:F,A3) -> 19 | C3: =B3/$B$8 -> 0.25675676 | D3: 意义/作用/价值——压回材料
A4: T2补表/补链 | B4: =COUNTIF(逐题回测·归位矩阵!F:F,A4) -> 12 | C4: =B4/$B$8 -> 0.16216216 | D4: 按表头逐格填
A5: T5对策/维权 | B5: =COUNTIF(逐题回测·归位矩阵!F:F,A5) -> 6 | C5: =B5/$B$8 -> 0.081081081 | D5: 你该怎么做/给指导
A6: T3辨析/评析 | B6: =COUNTIF(逐题回测·归位矩阵!F:F,A6) -> 3 | C6: =B6/$B$8 -> 0.040540541 | D6: 先判断后说理
A7: T6程序/纠错 | B7: =COUNTIF(逐题回测·归位矩阵!F:F,A7) -> 1 | C7: =B7/$B$8 -> 0.013513514 | D7: 程序适用·找错改正
A8: 合计 | B8: =SUM(B2:B7) -> 74

Sheet 考点频次
A1: 核心考点 | B1: 命中题数 | C1: 结论
A2: 民法原则 | B2: =COUNTIF(逐题回测·归位矩阵!H:H,"*"&A2&"*") -> 37 | C2: ★贯穿层(判案理由)，非节点
A3: 侵权·归责 | B3: =COUNTIF(逐题回测·归位矩阵!H:H,"*"&A3&"*") -> 37 | C3: ★骨干关系，最高频
A4: 合同 | B4: =COUNTIF(逐题回测·归位矩阵!H:H,"*"&A4&"*") -> 26
A5: 纠纷解决·程序 | B5: =COUNTIF(逐题回测·归位矩阵!H:H,"*"&A5&"*") -> 24 | C5: 独立环节④
A6: 知产·竞争 | B6: =COUNTIF(逐题回测·归位矩阵!H:H,"*"&A6&"*") -> 23
A7: 消费者 | B7: =COUNTIF(逐题回测·归位矩阵!H:H,"*"&A7&"*") -> 16
A8: 行为能力·效力 | B8: =COUNTIF(逐题回测·归位矩阵!H:H,"*"&A8&"*") -> 11 | C8: 前置·行为效力
A9: 主体资格 | B9: =COUNTIF(逐题回测·归位矩阵!H:H,"*"&A9&"*") -> 11 | C9: 前置·定双方
A10: 物权·相邻 | B10: =COUNTIF(逐题回测·归位矩阵!H:H,"*"&A10&"*") -> 10
A11: 婚姻家庭继承 | B11: =COUNTIF(逐题回测·归位矩阵!H:H,"*"&A11&"*") -> 9
A12: 劳动 | B12: =COUNTIF(逐题回测·归位矩阵!H:H,"*"&A12&"*") -> 8
A13: 生命身体健康权 | B13: =COUNTIF(逐题回测·归位矩阵!H:H,"*"&A13&"*") -> 4
A14: 隐私·个人信息 | B14: =COUNTIF(逐题回测·归位矩阵!H:H,"*"&A14&"*") -> 4
A15: 名誉权 | B15: =COUNTIF(逐题回测·归位矩阵!H:H,"*"&A15&"*") -> 3
A16: 诉讼时效 | B16: =COUNTIF(逐题回测·归位矩阵!H:H,"*"&A16&"*") -> 2
A17: 肖像权 | B17: =COUNTIF(逐题回测·归位矩阵!H:H,"*"&A17&"*") -> 1

Sheet 框架定稿(生命线×题型)
B1: 法律主观题 · 生命线 × 题型 双轴框架（从74题逐题回测长出）
B3: 【主轴·生命线】把一道纠纷从头到尾串起；每题先走这条链，按主导环节归位：
B4: ① 定双方·叫权利：自然人/法人/非法人·行为能力·AI非主体 ＋ 先叫准权利名（人格权/物权/知产/债权/身份权）
B5: ② 辨关系·套规则：合同/侵权/相邻/婚姻继承/劳动/消费/竞争 ＋ 套规则；〔贯穿层〕民法原则=判案理由(37/74)；权利边界
B6: ③ 审判·定责任：以事实为据法律为绳→定结论定责；举证责任＋诉讼时效；对策/维权策略
B7: ④ 解纷·给救济：协商·调解·仲裁·诉讼；管辖·代理·回避·证据·程序纠错→救济路径
B8: ⑤ 贯穿·升价值：意义题19道+每环收尾；意义句必须压回材料
B10: 【副轴·题型】决定答题动作与采分结构（一题一型）：T1判责33 · T4意义19 · T2补表12 · T5对策6 · T3辨析3 · T6纠错1
B12: 【数据逼出的5条硬结论（框架定稿要点）】
B13: 1. 民法原则命中37/74 → 是贯穿"判案理由"层，单列，绝不当并列专题。
B14: 2. 侵权·归责命中37/74 → 骨干关系，环②里以侵权四要件/归责/特殊责任为主干。
B15: 3. 多数题一题命中3–5个考点（复合）→ 拒绝codex单一专题(A1–A10)归类，必须按生命线排序。
... B19: 【与AB双轴/旧框架的关系】保留AB的"题型副轴"(唯一有逻辑的一半)；废弃扁平A1–A10；知识改挂生命线。不参考已淘汰的"争点"框架。

Sheet 缺口与外溢
A1: 类别 | B1: 条目 | C1: 说明
A2: 细则缺口 | B2: 2026朝阳二模18 | C2: 原卷官方细则未全收，答案据题面+通用规则，建议回卷核定
A3: 待OCR | B3: 2026朝阳期末·纯扫描卷 | C3: 文本层为空，需OCR确认是否含选必二法律主观题
A4: 待OCR | B4: 2026丰台一模(整卷扫描) | C4: 法律题已核为第20题(安全保障)，其余子问待OCR复核
A5: 期中存疑 | B5: 2024/2026朝阳期中、海淀期中 | C5: 期中多不考选必二法律；海淀婚姻题已收A7
A6: 外溢·必修三 | B6: 校园欺凌/OpenClaw/数字法院等12题 | C6: 涉科学立法·严格执法·公正司法·全民守法，标注
A7: 外溢·必修四经济 | B7: 2025西城一模20 | C7: 综合运用经济+法律，公平与效率
A8: 涉外法治 | B8: 2026房山二模17 | C8: 涉外法治建设，偏必修三/时政，标注
